testdata/golden/mix-heavy.golden
replay v1 500 300 349 62 58 31
fill 0 3 2 99430 527 buy
fill 1 4 2 99430 229 buy
fill 2 7 6 99415 613 buy
fill 3 11 6 99415 288 buy
fill 4 11 2 99430 193 buy
fill 5 11 9 99763 344 buy
fill 6 13 9 99763 274 buy
fill 7 6 9 99763 350 buy
fill 8 6 5 100117 139 buy
fill 9 14 5 100117 186 buy
fill 10 16 5 100117 181 buy
fill 11 18 5 100117 144 buy
fill 12 18 15 100239 395 buy
fill 13 18 10 100427 377 buy
fill 14 20 10 100427 102 buy
fill 15 20 8 100455 50 buy
fill 16 20 19 100545 526 buy
fill 17 15 22 100509 557 sell
fill 18 29 22 100509 257 sell
fill 19 29 28 100261 146 sell
fill 20 31 30 100004 614 buy
fill 21 31 29 100091 78 buy
fill 22 33 2 99852 84 sell
fill 23 34 29 100091 318 buy
fill 24 34 19 100545 240 buy
fill 25 34 27 100671 67 buy
fill 26 35 27 100671 656 buy
fill 27 40 24 100858 700 buy
fill 28 42 35 100845 34 sell
fill 29 42 36 100828 745 sell
fill 30 35 36 100828 53 sell
fill 31 44 37 100439 345 sell
fill 32 27 37 100439 369 sell
fill 33 27 9 100422 94 sell
fill 34 27 19 100094 297 sell
fill 35 49 47 100328 625 buy
fill 36 49 43 100500 348 buy
fill 37 52 43 100500 353 buy
fill 38 53 19 100094 232 sell
fill 39 53 50 100020 309 sell
fill 40 54 50 100020 72 sell
fill 41 56 50 100020 269 sell
fill 42 56 39 99781 555 sell
fill 43 56 10 99712 167 sell
fill 44 30 43 100500 275 buy
fill 45 30 35 100635 211 buy
fill 46 55 57 100559 339 sell
fill 47 8 10 99712 307 sell
fill 48 8 46 99660 172 sell
fill 49 59 46 99660 232 sell
fill 50 59 23 99621 467 sell
fill 51 59 45 99468 119 sell
fill 52 19 55 99855 217 buy
fill 53 19 35 100635 28 buy
fill 54 28 19 100703 7 sell
fill 55 60 19 100703 201 sell
fill 56 60 45 99468 97 sell
fill 57 60 10 99441 499 sell
fill 58 60 21 99286 28 sell
fill 59 61 37 99782 351 sell
fill 60 62 45 100477 83 sell
fill 61 66 64 100719 113 sell
fill 62 67 64 100719 42 sell
fill 63 67 45 100477 402 sell
fill 64 69 24 100858 247 buy
fill 65 70 43 100672 183 sell
fill 66 73 43 100672 48 sell
fill 67 75 24 100858 42 buy
fill 68 75 51 100873 422 buy
fill 69 75 58 100929 188 buy
fill 70 76 75 100941 128 sell
fill 71 76 43 100672 121 sell
fill 72 39 43 100672 4 sell
fill 73 2 43 100672 73 sell
fill 74 2 45 100477 266 sell
fill 75 2 74 100443 518 sell
fill 76 75 74 100443 47 sell
fill 77 75 65 100313 430 sell
fill 78 79 29 100955 378 sell
fill 79 79 63 100373 338 sell
fill 80 79 65 100313 79 sell
fill 81 9 65 100313 22 sell
fill 82 80 48 100528 236 buy
fill 83 81 48 100528 717 buy
fill 84 84 1 100967 452 buy
fill 85 84 32 101756 233 buy
fill 86 85 81 100902 189 sell
fill 87 65 85 100440 485 buy
fill 88 57 65 101217 11 sell
fill 89 87 65 101217 282 sell
fill 90 88 65 101217 179 sell
fill 91 88 55 100305 590 sell
fill 92 88 19 99992 82 sell
fill 93 85 32 101756 108 buy
fill 94 91 90 102287 182 buy
fill 95 94 35 102839 22 buy
fill 96 97 35 102839 241 buy
fill 97 99 85 102199 800 sell
fill 98 99 95 100899 114 sell
fill 99 100 98 102865 710 buy
fill 100 103 95 100899 281 sell
fill 101 105 95 100899 460 sell
fill 102 107 95 100899 135 sell
fill 103 107 106 100896 729 sell
fill 104 109 106 100896 216 sell
fill 105 109 19 100742 567 sell
fill 106 110 90 100938 132 sell
fill 107 110 19 100742 261 sell
fill 108 115 112 100615 95 sell
fill 109 114 112 100615 452 sell
fill 110 119 113 100641 388 buy
fill 111 119 110 101229 115 buy
fill 112 121 116 100466 868 sell
fill 113 123 116 100466 110 sell
fill 114 123 111 100349 42 sell
fill 115 51 111 100349 21 sell
fill 116 51 108 100213 312 sell
fill 117 22 101 102399 169 buy
fill 118 126 125 103524 166 buy
fill 119 127 55 105120 95 buy
fill 120 128 126 104303 101 sell
fill 121 128 22 102829 693 sell
fill 122 129 22 102829 121 sell
fill 123 131 129 102576 433 buy
fill 124 132 108 100716 469 sell
fill 125 132 122 100476 200 sell
fill 126 133 122 100476 237 sell
fill 127 133 93 100110 73 sell
fill 128 133 124 100063 640 sell
fill 129 136 58 100124 467 sell
fill 130 139 58 100124 483 sell
fill 131 139 124 100063 34 sell
fill 132 139 26 100047 378 sell
fill 133 139 47 100034 22 sell
fill 134 140 47 100034 84 sell
fill 135 140 117 99909 326 sell
fill 136 140 24 99871 514 sell
fill 137 141 24 99871 207 sell
fill 138 141 37 99782 90 sell
fill 139 141 92 99759 5 sell
fill 140 142 138 100258 240 buy
fill 141 143 92 99759 387 sell
fill 142 143 86 99665 272 sell
fill 143 143 120 99560 66 sell
fill 144 146 145 99874 158 buy
fill 145 148 147 99666 610 buy
fill 146 148 145 99874 98 buy
fill 147 150 120 99560 16 sell
fill 148 37 120 99560 576 sell
fill 149 37 135 99537 272 sell
fill 150 152 145 99874 23 buy
fill 151 154 145 99874 413 buy
fill 152 154 151 99944 585 buy
fill 153 163 161 99872 151 sell
fill 154 163 21 99574 721 sell
fill 155 164 151 99944 70 buy
fill 156 165 21 99574 223 sell
fill 157 165 118 99457 776 sell
fill 158 166 151 99944 84 buy
fill 159 167 43 100342 263 buy
fill 160 169 166 100273 14 sell
fill 161 170 162 100370 294 buy
fill 162 170 158 100387 161 buy
fill 163 171 158 100387 22 buy
fill 164 111 166 100273 117 sell
fill 165 172 158 100420 480 buy
fill 166 172 168 100494 102 buy
fill 167 172 117 100569 307 buy
fill 168 175 117 100569 671 buy
fill 169 177 166 100273 182 sell
fill 170 177 174 99921 257 sell
fill 171 166 177 99725 406 buy
fill 172 166 117 100569 13 buy
fill 173 178 166 100583 359 sell
fill 174 178 83 99565 509 sell
fill 175 160 180 100604 519 sell
fill 176 181 83 99826 498 sell
fill 177 183 181 99531 52 buy
fill 178 184 181 99531 5 buy
fill 179 184 182 99707 166 buy
fill 180 47 160 100114 294 buy
fill 181 47 138 100645 570 buy
fill 182 186 138 100645 171 buy
fill 183 187 138 100645 251 buy
fill 184 187 24 100797 140 buy
fill 185 187 137 100829 68 buy
fill 186 188 187 100845 82 sell
fill 187 188 32 100647 639 sell
fill 188 188 185 100538 127 sell
fill 189 89 185 100538 368 sell
fill 190 89 149 100479 334 sell
fill 191 89 189 100231 40 sell
fill 192 190 10 100869 207 buy
fill 193 190 176 100882 258 buy
fill 194 191 189 100231 486 sell
fill 195 192 189 100231 253 sell
fill 196 193 192 100121 2 buy
fill 197 195 176 100882 278 buy
fill 198 196 193 100546 824 sell
fill 199 117 193 100546 95 sell
fill 200 117 19 100413 280 sell
fill 201 197 176 100882 31 buy
fill 202 199 19 100413 158 sell
fill 203 199 194 100409 467 sell
fill 204 200 194 100409 174 sell
fill 205 82 194 100409 79 sell
fill 206 82 35 99928 150 sell
fill 207 82 184 99904 324 sell
fill 208 201 198 100795 345 buy
fill 209 201 176 100882 109 buy
fill 210 203 201 100898 7 sell
fill 211 158 184 99904 255 sell
fill 212 158 202 99648 201 sell
fill 213 58 158 99549 141 buy
fill 214 58 203 100130 257 buy
fill 215 58 204 100153 1 buy
fill 216 58 144 100532 483 buy
fill 217 206 58 100772 87 sell
fill 218 22 206 99810 423 buy
fill 219 22 208 100142 49 buy
fill 220 96 209 100421 39 sell
fill 221 211 113 100770 355 sell
fill 222 211 209 100421 59 sell
fill 223 212 210 100865 522 buy
fill 224 212 207 100943 65 buy
fill 225 213 207 100943 96 buy
fill 226 204 209 100421 139 sell
fill 227 204 22 100274 230 sell
fill 228 216 215 100927 489 buy
fill 229 36 22 100274 59 sell
fill 230 36 58 100009 200 sell
fill 231 36 214 100003 14 sell
fill 232 138 215 100927 157 buy
fill 233 138 207 100943 308 buy
fill 234 217 214 100003 152 sell
fill 235 208 217 99840 120 buy
fill 236 208 218 99847 475 buy
fill 237 221 208 100207 95 sell
fill 238 223 222 100649 434 buy
fill 239 147 208 100207 216 sell
fill 240 147 219 100066 29 sell
fill 241 224 222 100649 210 buy
fill 242 225 224 100673 71 sell
fill 243 227 224 100673 63 sell
fill 244 228 202 100998 17 buy
fill 245 230 202 100998 165 buy
fill 246 230 134 101058 99 buy
fill 247 231 224 100673 617 sell
fill 248 232 231 100036 207 buy
fill 249 235 234 99990 583 sell
fill 250 235 220 99782 76 sell
fill 251 236 231 100036 129 buy
fill 252 238 29 100654 55 buy
fill 253 239 237 100195 664 sell
fill 254 240 239 100126 76 buy
fill 255 240 29 100654 415 buy
fill 256 240 134 100673 167 buy
fill 257 245 236 100104 783 sell
fill 258 245 217 99666 40 sell
fill 259 248 246 100197 142 buy
fill 260 248 243 100354 34 buy
fill 261 242 247 100016 557 sell
