testdata/real/corpus_aapl_50k.txt
Add 16113575 1 18 5853300
Add 16113584 1 18 5853200
Add 16113594 1 18 5853100
Add 16120456 0 18 5859100
Add 16120480 0 18 5859200
Add 16120503 0 18 5859300
Add 16127688 1 100 5850000
Add 16166035 0 100 5859300
Cxl 16113594
Cxl 16113584
Cxl 16120456
Cxl 16120503
Cxl 16120480
Add 16166175 1 2 5849900
Add 16167159 1 18 5853600
Add 16167166 1 18 5853500
Add 3647217 1 20 5857300
Add 5740544 0 40 5857400
Add 2109823 1 50 5857000
Add 3570647 0 50 5857500
Add 3237773 1 20 5856900
Add 3647221 0 5 5857500
Add 3583158 1 5 5856500
Add 3647222 0 7 5857500
Add 3647220 1 20 5856400
Add 5230851 0 20 5857500
Add 4731250 1 3 5856000
Add 1373927 0 25 5857800
Add 1601225 0 20 5857800
Add 2606421 0 4 5858000
Add 1364835 0 5 5858200
Add 7277867 0 7 5858300
Cxl 16167159
Cxl 16113575
Cxl 16167166
Cxl 5740544
Mod 3570647 25 5857500
Mod 3647217 19 5857300
Mod 3647217 9 5857300
Cxl 3570647
Cxl 3647221
Cxl 3647222
Cxl 5230851
Cxl 1373927
Cxl 1601225
Cxl 2606421
Cxl 1364835
Cxl 7277867
Mod 16166035 63 5859300
Add 16182629 1 100 5852500
Add 16182649 1 50 5857400
Add 16183794 1 18 5857700
Add 16183801 1 18 5857600
Add 16183806 1 18 5857500
Add 16186225 1 100 5857000
Add 16196199 0 100 5859300
Mod 16166035 59 5859300
Add 16207125 0 100 5859400
Cxl 16182649
Cxl 16183801
Cxl 16183806
Add 16207170 0 100 5859900
Add 16207442 0 200 5859800
Cxl 16183794
Cxl 3647217
Mod 2109823 27 5857000
Add 16211220 0 18 5859200
Cxl 16186225
Add 16220046 1 100 5854500
Add 16225065 0 300 5870000
Add 16225109 0 300 5870000
Cxl 16220046
Add 16235607 0 5 5863300
Cxl 16196199
Cxl 16211220
Add 16249592 1 100 5854400
Add 16265081 1 100 5854500
Add 16265573 0 100 5858700
Add 16265761 1 67 5854400
Mod 2109823 26 5857000
Cxl 16265081
Add 16284218 1 100 5857000
Cxl 16284218
Add 16284304 1 100 5854500
Add 16291236 1 18 5857000
Add 16291244 1 18 5857100
Cxl 16284304
Add 16291389 1 100 5856000
Cxl 16291389
Add 16291456 1 100 5856100
Add 16294463 1 100 5857400
Add 16295892 0 100 5858900
Cxl 16291236
Cxl 16291244
Cxl 16291456
Cxl 16294463
Add 16309766 1 100 5854200
Cxl 2109823
Cxl 3237773
Add 16310817 1 18 5856600
Cxl 16309766
Add 16310958 1 100 5854600
Cxl 16310958
Add 16311061 1 100 5855400
Cxl 16311061
Add 16314560 1 100 5855600
Add 16316688 1 18 5856900
Cxl 16314560
Add 16316953 1 100 5855100
Add 3647224 1 15 5855900
Add 4566937 0 5 5859800
Add 4725584 1 1 5855500
Add 4725977 0 15 5859900
Add 2118573 1 9 5855000
Add 2109819 0 100 5860000
Add 3562118 1 5 5855000
Add 2126847 0 120 5860000
Add 9480911 1 25 5855000
Add 2851758 0 3 5860000
Add 2881480 0 25 5860000
Add 3305469 0 20 5860000
Add 3559332 0 3 5860000
Add 3569136 0 8 5860000
Add 3647225 0 20 5860000
Add 3689528 0 65 5860000
Add 4730816 0 50 5860000
Add 4985450 0 10 5860000
Add 5395985 0 1 5860000
Add 6325489 0 500 5860000
Add 9433882 0 35 5860000
Add 9303209 0 18 5865000
Add 10296777 0 40 5865000
Cxl 16316953
Add 16335544 1 100 5855000
Cxl 16335544
Cxl 16310817
Cxl 16316688
Add 16337151 1 100 5854700
Cxl 3583158
Cxl 3647220
Cxl 4731250
Cxl 3647224
Cxl 4725584
Cxl 2118573
Cxl 3562118
Cxl 9480911
Add 16337399 0 18 5858700
Add 16337407 0 5 5858600
Add 16337408 0 13 5858600
Add 16337414 1 18 5854800
Add 16337423 0 18 5858400
Add 16337430 0 18 5858500
Add 16337440 0 3 5858600
Cxl 16337151
Add 16337597 1 100 5854200
Add 16338748 1 15 5854900
Add 16339418 0 15 5858300
Cxl 16207170
Cxl 16337414
Cxl 16337399
Cxl 16337423
Cxl 16337407
Cxl 16337408
Cxl 16337430
Cxl 16337440
Cxl 16338748
Cxl 16207125
Cxl 16207442
Add 16365896 0 100 5858000
Add 16368700 0 200 5858900
Cxl 16339418
Add 16380157 0 18 5857700
Add 16380182 0 18 5857800
Add 16380189 0 18 5857900
Add 16380190 0 18 5858000
Add 16396043 1 18 5854700
Add 16396051 1 5 5854600
Cxl 16380189
Cxl 16380157
Cxl 16380182
Cxl 16380190
Add 16402634 0 18 5857700
Add 16402643 0 18 5857800
Add 16402646 0 18 5857900
Add 16402650 0 18 5858000
Cxl 16396043
Cxl 16396051
Add 16415481 0 13 5857600
Cxl 16402646
Cxl 16402643
Cxl 16402650
Add 16415792 0 18 5857300
Add 16415796 0 18 5857500
Add 16415798 0 18 5857400
Add 16415801 0 9 5857600
Cxl 16402634
Cxl 16415796
Cxl 16415481
Cxl 16415801
Cxl 16415798
Add 16445672 0 18 5857300
Add 16445684 0 10 5857200
Add 16445687 0 8 5857200
Add 16445707 0 18 5857200
Cxl 16337597
Add 16449896 1 100 5854400
Cxl 16449896
Add 16450945 1 100 5854200
Cxl 16368700
Cxl 16445687
Cxl 16445707
Cxl 16415792
Cxl 16445672
Cxl 16445684
Add 16467671 0 100 5858100
Cxl 16450945
Add 16479076 1 100 5856900
Cxl 16479076
Add 16479170 1 100 5854200
Add 16486693 0 18 5857700
Add 16486703 0 8 5857900
Add 16486709 0 18 5857800
Add 16486714 0 10 5857900
Add 16486717 0 18 5858000
Cxl 16479170
Add 16488533 1 100 5854700
Add 16497956 0 18 5857400
Add 16497960 0 4 5857500
Cxl 16486703
Cxl 16486709
Cxl 16486714
Cxl 16486717
Add 16497983 0 18 5857100
Add 16497988 0 2 5857200
Add 16502634 0 100 5857100
Add 16504889 0 18 5856800
Add 16504892 0 16 5856900
Cxl 16488533
Cxl 16504889
Cxl 16504892
Add 16527925 1 66 5857000
Cxl 16486693
Cxl 16497956
Cxl 16497960
Cxl 16497988
Cxl 16497983
Cxl 16527925
Add 16527982 1 18 5854500
Add 16535218 0 18 5856800
Add 16535225 0 18 5856900
Add 16535228 0 18 5857000
Add 16535234 0 18 5857100
Add 16538191 1 10 5854600
Cxl 16527982
Add 16539283 0 12 5856500
Cxl 16539283
Cxl 16535218
Add 16554356 1 18 5854600
Cxl 16535228
Cxl 16535225
Cxl 16535234
Add 16556387 1 100 5853700
Add 16556599 1 10 5854700
Add 16563530 0 18 5856800
Add 16563536 0 18 5856900
Add 16563538 0 18 5857000
Add 16563541 0 16 5857100
Add 11599111 1 230 5853000
Add 13126986 1 10 5851700
Cxl 16538191
Cxl 16563536
Cxl 16563541
Cxl 16554356
Cxl 16556599
Cxl 16563530
Cxl 16563538
Add 16617159 1 18 5854500
Add 16632807 1 18 5854700
Add 16632813 1 2 5854600
Cxl 16502634
Add 16655686 0 16 5857900
Add 16655691 0 18 5858000
Cxl 16617159
Cxl 16632807
Cxl 16632813
Add 16658480 1 18 5854700
Add 16658483 1 18 5854600
Add 16658486 1 2 5854500
Add 16661173 0 18 5857600
Add 16661182 0 18 5857700
Cxl 16556387
Cxl 16655686
Cxl 16658483
Cxl 16655691
Cxl 16658480
Cxl 16658486
Cxl 16661182
Cxl 16661173
Add 16675424 0 16 5857900
Add 16675431 0 18 5858000
Add 16675936 1 100 5854700
Add 16675969 0 900 5856800
Add 16679201 0 18 5856700
Add 16704576 1 18 5855000
Add 16704590 1 18 5854900
Add 16704592 1 2 5854800
Cxl 16675424
Cxl 16675431
Cxl 16679201
Mod 16675969 850 5856800
Cxl 16704576
Cxl 16704590
Cxl 16704592
Add 16730960 0 100 5856800
Add 16746392 0 18 5856500
Cxl 16730960
Add 16752894 0 100 5856500
Cxl 16746392
Mod 16752894 37 5856500
Cxl 16752894
Mod 16675969 587 5856800
Add 16779043 1 18 5854700
Add 16779073 1 14 5854800
Mod 16675969 455 5856800
Mod 16675969 396 5856800
Add 16781704 0 18 5856700
Add 16818091 1 7 5854800
Cxl 16779043
Cxl 16779073
Cxl 16781704
Add 16818125 1 53 5854800
Add 16818137 1 52 5854800
Add 16818156 1 1 5854800
Add 16818175 1 5 5854800
Add 16818181 1 45 5854800
Add 16818182 1 39 5854800
Add 16818198 1 27 5854800
Add 16841958 0 18 5856600
Cxl 16841958
Add 16879396 0 100 5858000
Cxl 16182629
Add 16898660 0 2 5856800
Add 16914630 1 100 5854900
Cxl 16818091
Cxl 16818125
Cxl 16818137
Cxl 16818156
Add 16939575 1 42 5854900
Cxl 16265761
Cxl 16818175
Add 16948611 0 320 5856800
Add 16948722 0 320 5856800
Mod 16675969 171 5856800
Add 16949037 1 67 5854900
Cxl 16948611
Add 16949716 0 320 5856800
Cxl 16818181
Mod 16675969 143 5856800
Add 16950346 1 18 5855000
Cxl 16950346
Cxl 16914630
Cxl 16939575
Mod 16949037 27 5854900
Add 16957682 0 18 5856800
Add 16957685 0 18 5856700
Cxl 16949037
Cxl 16818182
Cxl 16818198
Mod 16675936 66 5854700
Add 16958115 0 2 5856600
Cxl 16675936
Add 16958771 1 66 5854900
Cxl 16958771
Mod 16249592 66 5854400
Add 16959555 0 169 5856600
Cxl 16959555
Add 16959614 0 169 5856600
Cxl 16959614
Add 16959673 0 169 5856600
Cxl 16959673
Add 16972144 1 18 5854700
Add 16972157 1 4 5854600
Add 16972164 0 200 5859100
Cxl 16957682
Cxl 16957685
Cxl 16958115
Add 16979328 0 18 5856500
Add 16979334 0 18 5856600
Add 16979338 0 18 5856700
Add 16979339 0 18 5856800
Cxl 16948722
Cxl 16972144
Cxl 16972157
Cxl 16972164
Cxl 16979338
Cxl 16979334
