testdata/real/corpus_aapl_50k.golden
replay v1 50000 1180 24915 1043 24042 0
fill 0 19300531 17478659 5849900 100 sell
fill 1 21737996 16235607 5863300 5 buy
fill 2 21924952 21730687 5868800 3 buy
fill 3 21955057 21730687 5868800 15 buy
fill 4 22056947 21996460 5866300 100 sell
fill 5 22057983 21996460 5866300 60 sell
fill 6 22058463 21996460 5866300 40 sell
fill 7 22487239 22117139 5874100 100 buy
fill 8 22630725 22120201 5874100 100 buy
fill 9 22630725 22121763 5874100 100 buy
fill 10 25280435 24338897 5873200 100 buy
fill 11 26809002 26098508 5867500 100 sell
fill 12 26893589 25828450 5866000 5 sell
fill 13 26894198 25828450 5866000 95 sell
fill 14 26943796 25821920 5864900 100 sell
fill 15 26957190 25787319 5864600 100 sell
fill 16 26960312 25834435 5863700 100 sell
fill 17 26984515 22837120 5863100 100 sell
fill 18 27068821 25872774 5862700 100 sell
fill 19 27075901 24053243 5862400 5 sell
fill 20 27075901 24063691 5862300 5 sell
fill 21 27075901 24073634 5862200 5 sell
fill 22 27075901 23602998 5862100 25 sell
fill 23 27075901 24081764 5862100 5 sell
fill 24 27075901 25079416 5862100 100 sell
fill 25 27075901 24102686 5862000 5 sell
fill 26 27172430 23816303 5860100 1 sell
fill 27 27285864 22249317 5858500 87 sell
fill 28 27285869 22249317 5858500 13 sell
fill 29 27288078 22297532 5857700 100 sell
fill 30 27529004 22297532 5857700 14 sell
fill 31 27530857 22297532 5857700 86 sell
fill 32 32357756 31724075 5865200 42 buy
fill 33 32446777 31724075 5865200 18 buy
fill 34 32463755 31724075 5865200 18 buy
fill 35 33820177 31724075 5865200 3 buy
fill 36 33821413 31724075 5865200 100 buy
fill 37 33823360 31724075 5865200 19 buy
fill 38 33823360 29513612 5865400 100 buy
fill 39 33823360 29908825 5865700 100 buy
fill 40 33823360 31702738 5865800 100 buy
fill 41 33823360 30732677 5866200 100 buy
fill 42 33823360 30981156 5866600 25 buy
fill 43 34128243 31750407 5866900 1 buy
fill 44 34160132 31750407 5866900 99 buy
fill 45 34160132 31125582 5867000 1 buy
fill 46 34163221 31125582 5867000 99 buy
fill 47 34163221 32863342 5867200 1 buy
fill 48 34174023 32863342 5867200 99 buy
fill 49 34226122 33910330 5867400 100 buy
fill 50 35241508 34748380 5863300 100 sell
fill 51 36097150 34093919 5861900 11 sell
fill 52 36806006 34093919 5861900 89 sell
fill 53 36810778 33871842 5861200 100 sell
fill 54 38388366 33141505 5860400 100 sell
fill 55 38388368 34377179 5860400 100 sell
fill 56 38388369 34377179 5860400 100 sell
fill 57 38395235 34377179 5860400 100 sell
fill 58 38395468 34377179 5860400 200 sell
fill 59 38395469 34377179 5860400 100 sell
fill 60 38395471 34377179 5860400 100 sell
fill 61 38395492 34377179 5860400 100 sell
fill 62 38395985 34377179 5860400 100 sell
fill 63 38395986 34377179 5860400 100 sell
fill 64 38395991 32270861 5860000 100 sell
fill 65 38396007 33159639 5860000 100 sell
fill 66 38396019 33159639 5860000 75 sell
fill 67 38396019 37375974 5860000 25 sell
fill 68 38396047 37375974 5860000 75 sell
fill 69 38396047 33110831 5859900 25 sell
fill 70 38396050 33110831 5859900 75 sell
fill 71 38396050 33112111 5859500 25 sell
fill 72 38396085 33112111 5859500 75 sell
fill 73 38396085 33739903 5859500 25 sell
fill 74 38396092 33739903 5859500 75 sell
fill 75 38396092 36867705 5859400 25 sell
fill 76 38396137 36867705 5859400 75 sell
fill 77 38396137 37250453 5859400 25 sell
fill 78 38396141 37250453 5859400 75 sell
fill 79 38396141 35132224 5859100 25 sell
fill 80 38396167 35132224 5859100 75 sell
fill 81 38396167 37296137 5858900 25 sell
fill 82 38396605 37296137 5858900 75 sell
fill 83 38396605 37054618 5858800 25 sell
fill 84 38407988 37054618 5858800 75 sell
fill 85 38411068 30008336 5858500 100 sell
fill 86 38412362 35069061 5858500 100 sell
fill 87 38412418 36696770 5858500 100 sell
fill 88 38433421 37771638 5858200 100 sell
fill 89 38437601 37771638 5858200 100 sell
fill 90 38439754 37771638 5858200 100 sell
fill 91 38439815 37771638 5858200 100 sell
fill 92 38559839 37771638 5858200 100 sell
fill 93 38559849 37771638 5858200 100 sell
fill 94 38560253 37771638 5858200 100 sell
fill 95 38560263 37771638 5858200 100 sell
fill 96 38579697 37771638 5858200 100 sell
fill 97 38579702 37771638 5858200 100 sell
fill 98 38586174 33102025 5857900 100 sell
fill 99 39256552 38668048 5861100 17 buy
fill 100 39258245 38584878 5861800 17 buy
fill 101 39641364 38562829 5862500 100 buy
fill 102 39641408 38901367 5862700 19 buy
fill 103 39641408 38898483 5862800 19 buy
fill 104 39646156 39081434 5863400 19 buy
fill 105 39646187 39142267 5863600 100 buy
fill 106 39646190 39050122 5863700 18 buy
fill 107 39691347 39050122 5863700 1 buy
fill 108 39691350 39047741 5863800 19 buy
fill 109 39691713 38439960 5863900 100 buy
fill 110 39718134 37818737 5864400 100 buy
fill 111 39917839 39123791 5864600 18 buy
fill 112 39917847 39123791 5864600 1 buy
fill 113 39918795 39269244 5865000 17 buy
fill 114 39919730 38091086 5865200 10 buy
fill 115 39920492 37910424 5865300 12 buy
fill 116 39926485 37910424 5865300 18 buy
fill 117 39926497 37910424 5865300 18 buy
fill 118 39926504 37910424 5865300 6 buy
fill 119 39929501 37910424 5865300 18 buy
fill 120 39929542 37910424 5865300 18 buy
fill 121 39929876 37910424 5865300 10 buy
fill 122 39929876 39468969 5865300 20 buy
fill 123 39929876 39395248 5865400 19 buy
fill 124 39929876 39269247 5865500 19 buy
fill 125 39929876 38380391 5865800 32 buy
fill 126 39930835 38380391 5865800 50 buy
fill 127 40239267 38380391 5865800 18 buy
fill 128 40251359 39390008 5866000 19 buy
fill 129 40251390 37631972 5866200 100 buy
fill 130 40252959 38372432 5866200 100 buy
fill 131 40252967 39285422 5866200 100 buy
fill 132 40253001 39285422 5866200 100 buy
fill 133 40267374 39285422 5866200 100 buy
fill 134 40267702 39285422 5866200 100 buy
fill 135 40267704 39285422 5866200 100 buy
fill 136 40267712 39285422 5866200 100 buy
fill 137 40268086 39285422 5866200 100 buy
fill 138 40268088 39285422 5866200 100 buy
fill 139 40268307 39285422 5866200 100 buy
fill 140 40279353 39285422 5866200 100 buy
fill 141 40288398 36017705 5866400 1 buy
fill 142 40335666 36017705 5866400 99 buy
fill 143 40335666 39261366 5866400 1 buy
fill 144 40607232 39261366 5866400 18 buy
fill 145 40638108 38005412 5866800 25 buy
fill 146 40737276 38005412 5866800 75 buy
fill 147 40747579 37885011 5867200 100 buy
fill 148 40816293 28910121 5867700 100 buy
fill 149 40816293 37580635 5867800 100 buy
fill 150 40880470 34869491 5868000 1 buy
fill 151 40881845 34869491 5868000 100 buy
fill 152 40891698 34869491 5868000 100 buy
fill 153 40906452 34869491 5868000 100 buy
fill 154 40929855 34869491 5868000 100 buy
fill 155 40929911 34869491 5868000 18 buy
fill 156 40929929 34869491 5868000 20 buy
fill 157 40930012 34869491 5868000 81 buy
fill 158 40930012 37463357 5868000 419 buy
fill 159 40930037 37463357 5868000 200 buy
fill 160 40930046 37463357 5868000 100 buy
fill 161 40930051 37463357 5868000 20 buy
fill 162 40930084 37463357 5868000 20 buy
fill 163 40930225 37463357 5868000 20 buy
fill 164 40930933 37463357 5868000 20 buy
fill 165 40937202 37463357 5868000 20 buy
fill 166 40940005 37463357 5868000 100 buy
fill 167 40940032 37463357 5868000 81 buy
fill 168 40940032 26810749 5868200 19 buy
fill 169 40940652 26810749 5868200 20 buy
fill 170 40943108 26810749 5868200 20 buy
fill 171 40945779 26810749 5868200 17 buy
fill 172 40946444 26810749 5868200 24 buy
fill 173 40946444 28190688 5868300 76 buy
fill 174 40946790 28190688 5868300 24 buy
fill 175 40946790 39705552 5868300 76 buy
fill 176 40949167 39705552 5868300 100 buy
fill 177 40954656 39705552 5868300 17 buy
fill 178 40963637 39705552 5868300 119 buy
fill 179 40963835 39705552 5868300 20 buy
fill 180 40966936 39705552 5868300 200 buy
fill 181 40972043 39705552 5868300 100 buy
fill 182 40972057 39705552 5868300 200 buy
fill 183 40974664 39705552 5868300 100 buy
fill 184 40974672 39705552 5868300 68 buy
fill 185 40974672 30596473 5868500 132 buy
fill 186 40974676 30596473 5868500 200 buy
fill 187 40977981 30596473 5868500 100 buy
fill 188 40978907 30596473 5868500 100 buy
